# 3.then 返回普通值

promise 支持多个 then 的链式调用，分三种情况

1. 第一个 then 返回普通值。无论是在 then 的 onFulfilled、onRejected 函数运行后，返回了普通值，都会在下一个 then 的 onFulfilled 接收到。如果没有返回值，默认为返回 undefined

2. 第一个 then 运行错误。无论是在 then 的 onFulfilled、onRejected 函数里，执行报错了，都会在下一个 then 的 onRejected 接收到。
3. 第一个 then 返回 promise。 会解析 promise，根据解析的后的结果传递给下一个 then。

##### 实现第一个 then 返回普通值的情况

```js
const enum STATUS { // 存放状态，ts枚举
  pending = 'PENDING',
  fulfilled = 'FULFILLED',
  rejected = 'REJECTED'
}

class Promise {
  status: STATUS;
  value: any;
  reason: any;
  onResolvedCallback: Function[];
  onRejectedCallback: Function[];
  constructor(executor) {
    this.status = STATUS.pending; // 当前状态
    this.value = undefined; // 成功原因
    this.reason = undefined;  // 失败原因
    this.onResolvedCallback = [];
    this.onRejectedCallback = [];

    const resolve = (value?: any) => { // 调resolve更改status状态，并把传入的value保存下来。加？表示value允许不传参
      if (this.status === STATUS.pending) { // 只有等待态时才允许修改状态和值，否则不生效
        this.status = STATUS.fulfilled;
        this.value = value;
        this.onResolvedCallback.forEach(fn => fn());
      }
    }
    const reject = (reason?: any) => { // 逻辑和resolve类似
      if (this.status === STATUS.pending) {
        this.status = STATUS.rejected;
        this.reason = reason;
        this.onRejectedCallback.forEach(fn => fn());
      }
    }

    try { // 如果promise初始执行报错，也走reject状态
      executor(resolve, reject)
    } catch (e) {
      reject(e)
    }
  }
  then(onFulfilled, onRejected) {
    let promise2 = new Promise((resolve, reject) => {
      if (this.status == STATUS.fulfilled) {
        let x = onFulfilled(this.value);
        resolve(x); // 用then的返回值，作为下一次then的成功结果
      }
      if (this.status == STATUS.rejected) {
        let x = onRejected(this.reason); // 这里x是普通值
        resolve(x);
      }
      if (this.status == STATUS.pending) { //如果executor()有异步代码，执行then时还是等待态，就把成功回调和失败回调存起来
        this.onResolvedCallback.push(() => { // 切片编程，套一层函数
          let x = onFulfilled(this.value);
          resolve(x);
        })
        this.onRejectedCallback.push(() => {
          let x = onRejected(this.reason); // 这里x是普通值
          resolve(x);
        })
      }
    });
    return promise2; // 为了实现链式调用的效果，返回一个新的promise
  }
}

export default Promise
```

##### 测试代码

```js
const Promise = require('./bundle');

let promise2 = new Promise((resolve, reject) => {
  reject('err'); // => success 1
  // resolve('data') // => success 100
}).then(
  data => {
    return 100;
  },
  err => {
    return 1; // 返回了普通值，也会走到下一个then的success。空白，走到下一个then的success，data是undefined
  },
);

promise2.then(
  data => {
    console.log('success', data);
  },
  err => {
    console.log('faild', err);
  },
);
```

总结：

有两个地方代码改动较大，

1.为了实现.then 的效果，不能返回 this，而是返回一个新的 promise，因为 promise 状态是不可逆的，不能先成功后失败或先失败后成功。

2.为了把运行 onFulfilled/onRejected 后返回的值传递到下一个 promise 的 then，需要取到并运行下一个 promise 的 resolve/reject，则把 onFulfilled/onRejected 的运行放入下一个 promise 的 executor，利用局部作用域取到，且 executor 是声明 promise 就立即执行的
