# 4.then 错误处理

##### 实现第一个 then 运行错误的情况

```js
const enum STATUS { // 存放状态，ts枚举
  pending = 'PENDING',
  fulfilled = 'FULFILLED',
  rejected = 'REJECTED'
}

class Promise {
  status: STATUS;
  value: any;
  reason: any;
  onResolvedCallback: Function[];
  onRejectedCallback: Function[];
  constructor(executor) {
    this.status = STATUS.pending; // 当前状态
    this.value = undefined; // 成功原因
    this.reason = undefined;  // 失败原因
    this.onResolvedCallback = [];
    this.onRejectedCallback = [];

    const resolve = (value?: any) => { // 调resolve更改status状态，并把传入的value保存下来。加？表示value允许不传参
      if (this.status === STATUS.pending) { // 只有等待态时才允许修改状态和值，否则不生效
        this.status = STATUS.fulfilled;
        this.value = value;
        this.onResolvedCallback.forEach(fn => fn());
      }
    }
    const reject = (reason?: any) => { // 逻辑和resolve类似
      if (this.status === STATUS.pending) {
        this.status = STATUS.rejected;
        this.reason = reason;
        this.onRejectedCallback.forEach(fn => fn());
      }
    }

    try { // 如果promise初始执行报错，也走reject状态
      executor(resolve, reject)
    } catch (e) {
      reject(e)
    }
  }
  then(onFulfilled, onRejected) {
    let promise2 = new Promise((resolve, reject) => {
      if (this.status == STATUS.fulfilled) {
        try {
          let x = onFulfilled(this.value);
          resolve(x);
        } catch (e) {
          reject(e);
        }
      }
      if (this.status == STATUS.rejected) {
        try {
          let x = onRejected(this.reason); // 这里x是普通值
          resolve(x);
        } catch (e) {
          reject(e);
        }
      }
      if (this.status == STATUS.pending) { //如果executor()有异步代码，执行then时还是等待态，就把成功回调和失败回调存起来
        this.onResolvedCallback.push(() => { // 切片编程，套一层函数
          try {
            let x = onFulfilled(this.value);
            resolve(x);
          } catch (e) {
            reject(e);
          }
        })
        this.onRejectedCallback.push(() => {
          try {
            let x = onRejected(this.reason); // 这里x是普通值
            resolve(x);
          } catch (e) {
            reject(e);
          }
        })
      }
    });
    return promise2; // 为了实现链式调用的效果，返回一个新的promise
  }
}

export default Promise
```

##### 测试代码

```js
const Promise = require('./bundle');

let promise2 = new Promise((resolve, reject) => {
  resolve('ok'); // => faild Error: err1
  // reject('no') // => faild Error: err2
}).then(
  data => {
    throw new Error('err1');
  },
  err => {
    throw new Error('err2');
  },
);

promise2.then(
  data => {
    console.log('success', data);
  },
  err => {
    console.log('faild', err);
  },
);

// faild Error: err1
```

总结：

把第一个 then 的函数运行(onFulfilled/onRejected)包在 try/catch 中，只要捕捉到了报错，就调用下一个 promise 的 resolve(走下一个 then 的 onRejected)
